
[32m[I 2024-05-29 16:01:37,102][39m A new study created in memory with name: no-name-86351ae5-6ac8-4b31-8530-3aace582c746
Training phase ...
Epoch 1 - Training:   0%|                                                                       | 0/257 [00:00<?, ?it/s]/home/disi/ml/.venv/lib/python3.11/site-packages/torch/autograd/graph.py:744: UserWarning: Plan failed with a cudnnException: CUDNN_BACKEND_EXECUTION_PLAN_DESCRIPTOR: cudnnFinalize Descriptor Failed cudnn_status: CUDNN_STATUS_NOT_SUPPORTED (Triggered internally at ../aten/src/ATen/native/cudnn/Conv_v8.cpp:919.)
  return Variable._execution_engine.run_backward(  # Calls into the C++ engine to run the backward pass







































Epoch 1 - Training:  99%|â–ˆâ–ˆâ–ˆâ–ˆâ–ˆâ–ˆâ–ˆâ–ˆâ–ˆâ–ˆâ–ˆâ–ˆâ–ˆâ–ˆâ–ˆâ–ˆâ–ˆâ–ˆâ–ˆâ–ˆâ–ˆâ–ˆâ–ˆâ–ˆâ–ˆâ–ˆâ–ˆâ–ˆâ–ˆâ–ˆâ–ˆâ–ˆâ–ˆâ–ˆâ–ˆâ–ˆâ–ˆâ–ˆâ–ˆâ–ˆâ–ˆâ–ˆâ–ˆâ–ˆâ–ˆâ–ˆâ–ˆâ–ˆâ–ˆâ–ˆâ–ˆâ–ˆâ–ˆâ–ˆâ–ˆâ–ˆâ–ˆâ–ˆâ–ˆâ–ˆâ–Œ| 255/257 [01:23<00:00,  3.19it/s]
Epoch 1 - Training: 100%|â–ˆâ–ˆâ–ˆâ–ˆâ–ˆâ–ˆâ–ˆâ–ˆâ–ˆâ–ˆâ–ˆâ–ˆâ–ˆâ–ˆâ–ˆâ–ˆâ–ˆâ–ˆâ–ˆâ–ˆâ–ˆâ–ˆâ–ˆâ–ˆâ–ˆâ–ˆâ–ˆâ–ˆâ–ˆâ–ˆâ–ˆâ–ˆâ–ˆâ–ˆâ–ˆâ–ˆâ–ˆâ–ˆâ–ˆâ–ˆâ–ˆâ–ˆâ–ˆâ–ˆâ–ˆâ–ˆâ–ˆâ–ˆâ–ˆâ–ˆâ–ˆâ–ˆâ–ˆâ–ˆâ–ˆâ–ˆâ–ˆâ–ˆâ–ˆâ–ˆâ–ˆ| 257/257 [01:24<00:00,  3.05it/s]
2024-05-29 16:03:03,430 - training_logger - INFO - Training: Average loss: 5.2550, Accuracy: 1.42%
2024-05-29 16:03:03,430 - training_logger - INFO - Epoch 1 completed in 84.31 seconds


Validation:  98%|â–ˆâ–ˆâ–ˆâ–ˆâ–ˆâ–ˆâ–ˆâ–ˆâ–ˆâ–ˆâ–ˆâ–ˆâ–ˆâ–ˆâ–ˆâ–ˆâ–ˆâ–ˆâ–ˆâ–ˆâ–ˆâ–ˆâ–ˆâ–ˆâ–ˆâ–ˆâ–ˆâ–ˆâ–ˆâ–ˆâ–ˆâ–ˆâ–ˆâ–ˆâ–ˆâ–ˆâ–ˆâ–ˆâ–ˆâ–ˆâ–ˆâ–ˆâ–ˆâ–ˆâ–ˆâ–ˆâ–ˆâ–ˆâ–ˆâ–ˆâ–ˆâ–ˆâ–ˆâ–ˆâ–ˆâ–ˆâ–ˆâ–ˆâ–ˆâ–ˆâ–ˆâ–ˆâ–ˆâ–ˆâ–ˆâ–ˆâ–ˆâ–ˆâ–ˆâ–‹ | 55/56 [00:05<00:00, 11.29it/s]
Train loss: 5.255, Train accuracy: 1.423
Validation: 100%|â–ˆâ–ˆâ–ˆâ–ˆâ–ˆâ–ˆâ–ˆâ–ˆâ–ˆâ–ˆâ–ˆâ–ˆâ–ˆâ–ˆâ–ˆâ–ˆâ–ˆâ–ˆâ–ˆâ–ˆâ–ˆâ–ˆâ–ˆâ–ˆâ–ˆâ–ˆâ–ˆâ–ˆâ–ˆâ–ˆâ–ˆâ–ˆâ–ˆâ–ˆâ–ˆâ–ˆâ–ˆâ–ˆâ–ˆâ–ˆâ–ˆâ–ˆâ–ˆâ–ˆâ–ˆâ–ˆâ–ˆâ–ˆâ–ˆâ–ˆâ–ˆâ–ˆâ–ˆâ–ˆâ–ˆâ–ˆâ–ˆâ–ˆâ–ˆâ–ˆâ–ˆâ–ˆâ–ˆâ–ˆâ–ˆâ–ˆâ–ˆâ–ˆâ–ˆâ–ˆâ–ˆ| 56/56 [00:05<00:00, 10.05it/s]
[33m[W 2024-05-29 16:03:09,010][39m Trial 0 failed with parameters: {'dropout_rate': 0.40218636048451706, 'optimizer': 'SGD', 'learning_rate': 0.0005252008490990323, 'weight_decay': 0.00021458506227505666, 'momentum': 0.8764771560624222} because of the following error: KeyError('checkpoint_path').
Traceback (most recent call last):
  File "/home/disi/ml/.venv/lib/python3.11/site-packages/optuna/study/_optimize.py", line 196, in _run_trial
    value_or_values = func(trial)
                      ^^^^^^^^^^^
  File "/home/disi/ml/intromlproject/training-main-optune.py", line 116, in objective
    save_path = os.path.join(config['checkpoint_path'], f"OPTUNA_trial{trial}_{config['model_name']}_{config['dataset_name']}_epoch{epoch}.pth")
                             ~~~~~~^^^^^^^^^^^^^^^^^^^
KeyError: 'checkpoint_path'
[33m[W 2024-05-29 16:03:09,011][39m Trial 0 failed with value None.
Traceback (most recent call last):
  File "/home/disi/ml/intromlproject/training-main-optune.py", line 172, in <module>
    main(config)
  File "/home/disi/ml/intromlproject/training-main-optune.py", line 126, in main
    study.optimize(objective, n_trials=trials, timeout=600)
  File "/home/disi/ml/.venv/lib/python3.11/site-packages/optuna/study/study.py", line 451, in optimize
    _optimize(
  File "/home/disi/ml/.venv/lib/python3.11/site-packages/optuna/study/_optimize.py", line 62, in _optimize
    _optimize_sequential(
  File "/home/disi/ml/.venv/lib/python3.11/site-packages/optuna/study/_optimize.py", line 159, in _optimize_sequential
    frozen_trial = _run_trial(study, func, catch)
                   ^^^^^^^^^^^^^^^^^^^^^^^^^^^^^^
  File "/home/disi/ml/.venv/lib/python3.11/site-packages/optuna/study/_optimize.py", line 247, in _run_trial
    raise func_err
  File "/home/disi/ml/.venv/lib/python3.11/site-packages/optuna/study/_optimize.py", line 196, in _run_trial
    value_or_values = func(trial)
                      ^^^^^^^^^^^
  File "/home/disi/ml/intromlproject/training-main-optune.py", line 116, in objective
    save_path = os.path.join(config['checkpoint_path'], f"OPTUNA_trial{trial}_{config['model_name']}_{config['dataset_name']}_epoch{epoch}.pth")
                             ~~~~~~^^^^^^^^^^^^^^^^^^^
KeyError: 'checkpoint_path'